<?xml version="1.0"?>

<robot name="billi" xmlns:xacro="http://www.ros.org/wiki/xacro">

<!-- billi body -->
<xacro:include filename="$(find billi_sim)/models/urdf/body.xacro"/>

<!-- billi leg -->
<xacro:include filename="$(find billi_sim)/models/urdf/leg1.xacro"/>
<xacro:include filename="$(find billi_sim)/models/urdf/leg2.xacro"/>
<xacro:include filename="$(find billi_sim)/models/urdf/leg3.xacro"/>
<xacro:include filename="$(find billi_sim)/models/urdf/leg4.xacro"/>
<xacro:include filename="$(find billi_sim)/models/urdf/leg-lower4.xacro"/>
<xacro:include filename="$(find billi_sim)/models/urdf/leg-lower2.xacro"/>
<xacro:include filename="$(find billi_sim)/models/urdf/leg-lower1.xacro"/>
<xacro:include filename="$(find billi_sim)/models/urdf/leg-lower3.xacro"/>
<xacro:include filename="$(find billi_sim)/models/urdf/paw.xacro"/>

<!-- billi head -->
<xacro:include filename="$(find billi_sim)/models/urdf/head.xacro"/>



<!-- _____________________________________________________________HEAD AND BODY JOINT_________________________________________________ -->
<!--head_body -->
    		<joint name="head_body" type="revolute">
			<origin xyz="0.08 -0.06 -0.22" rpy="0 0 0"/>
			<parent link="body"/>
			<child  link="head"/>
			<axis xyz="0 0 1"/>
			<limit effort="10.0" velocity="1.0"
          				lower="-0.08"
		  			upper="0.08"/>
		</joint>

		<gazebo reference="head_body">
			<provideFeedback>true</provideFeedback>
			<disableFixedJointLumping>true</disableFixedJointLumping>
		</gazebo>


<!-- _____________________________________________________________RIGHT HAND BOTH JOINTS_________________________________________________ -->
<!-- right_hand-->
    		<joint name="right_hand" type="revolute">
			<origin xyz="0 0 0" rpy="0 0 0"/>
			<parent link="body"/>
			<child  link="leg1"/>
			<axis xyz="0 0 1"/>
			<limit effort="10.0" velocity="1.0"
          					lower="-1.1"
		 				 upper="1.1"/>
		</joint>
	
		<gazebo reference="right_hand">
			<provideFeedback>true</provideFeedback>
			<disableFixedJointLumping>true</disableFixedJointLumping>
		</gazebo>

<!--lower_upper1 -->
		<joint name="lower_upper1" type="revolute">
			<origin xyz="0.0 -0.1964 0.0" rpy="0 0 0"/>
			<parent link="leg1"/>
			<child  link="leg-lower1"/>
			<axis xyz="0 0 1"/>
			<limit effort="10.0" velocity="1.0"
          					lower="-1.1"
		  				upper="1.1"/>
		</joint>
		
		<gazebo reference="lower_upper1">
			<provideFeedback>true</provideFeedback>
			<disableFixedJointLumping>true</disableFixedJointLumping>
		</gazebo>

<!--lower-feet -->
    		<joint name="leg1_feet" type="fixed">
			<origin xyz="0.11 -0.06 -0.30" rpy="0 1.57 -1.57"/>
			<parent link="leg-lower1"/>
			<child  link="paw"/>
			<axis xyz="0 0 1"/>
		</joint>

		<gazebo reference="leg1_feet">
			<provideFeedback>true</provideFeedback>
			<disableFixedJointLumping>true</disableFixedJointLumping>
		</gazebo>


<!-- _____________________________________________________________LEFT HAND BOTH JOINTS_________________________________________________ -->

<!--left_hand -->
   		<joint name="left_hand" type="revolute">
			<origin xyz="0 0 -0.46" rpy="0 0 0"/>
			<parent link="body"/>
			<child  link="leg4"/>
			<axis xyz="0 0 1"/>
			<limit effort="10.0" velocity="1.0"
          				lower="-1.1"
		 			upper="1.1"/>
		</joint>
		<gazebo reference="left_hand">
			<provideFeedback>true</provideFeedback>
			<disableFixedJointLumping>true</disableFixedJointLumping>
		</gazebo>


<!-- lower_upper4-->
		<joint name="lower_upper4" type="revolute">
			<origin xyz="0.0 -0.19641 0.0" rpy="0 0 0"/>
			<parent link="leg4"/>
			<child  link="leg-lower4"/>
			<axis xyz="0 0 1"/>
			<limit effort="10.0" velocity="1.0"
          					lower="-1.1"
		 				upper="1.1"/>
		</joint>
	
		<gazebo reference="lower_upper4">
			<provideFeedback>true</provideFeedback>
			<disableFixedJointLumping>true</disableFixedJointLumping>
		</gazebo>


<!-- _____________________________________________________________RIGHT LEG BOTH JOINTS_________________________________________________ -->


<!-- right_leg-->
		<joint name="right_leg" type="revolute">
			<origin xyz=".415 .085 0" rpy="0 0 0"/>
			<parent link="body"/>
			<child  link="leg2"/>
			<axis xyz="0 0 1"/>
			<limit effort="10.0" velocity="1.0"
          					lower="-1.1"
		 				 upper="1.1"/>
		</joint>
		<gazebo reference="right_leg">
			<provideFeedback>true</provideFeedback>
			<disableFixedJointLumping>true</disableFixedJointLumping>
		</gazebo>



<!-- lower_upper2-->
		<joint name="lower_upper2" type="revolute">
			<origin xyz="0.0 -0.19641 0.0" rpy="0 0 0"/>
			<parent link="leg2"/>
			<child  link="leg-lower2"/>
			<axis xyz="0 0 1"/>
			<limit effort="10.0" velocity="1.0"
         					 lower="-1.1"
		 				 upper="1.1"/>
		</joint>
		
		<gazebo reference="lower_upper2">
				<provideFeedback>true</provideFeedback>
				<disableFixedJointLumping>true</disableFixedJointLumping>
		</gazebo>



<!-- _____________________________________________________________LEFT LEG BOTH JOINTS_________________________________________________ -->


<!--left_leg -->
    		<joint name="left_leg" type="revolute">
			<origin xyz="0.415 0.085 -0.46" rpy="0 0 0"/>
			<parent link="body"/>
			<child  link="leg3"/>
			<axis xyz="0 0 1"/>
			<limit effort="10.0" velocity="1.0"
          					lower="-1.1"
		 				 upper="1.1"/>
		</joint>
	
		<gazebo reference="left_leg">
			<provideFeedback>true</provideFeedback>
			<disableFixedJointLumping>true</disableFixedJointLumping>
		</gazebo>




<!-- lower_upper3-->
		<joint name="lower_upper3" type="revolute">
			<origin xyz="0.0 -0.18641 0.0" rpy="0 0 0"/>
			<parent link="leg3"/>
			<child  link="leg-lower3"/>
			<axis xyz="0 0 1"/>
			<limit effort="10.0" velocity="1.0"
          					lower="-1.1"
		 				upper="1.1"/>
		</joint>

		<gazebo reference="lower_upper3">
			<provideFeedback>true</provideFeedback>
			<disableFixedJointLumping>true</disableFixedJointLumping>
		</gazebo>


<!--___________________________________________________ Adding transmissions_____________________________________________________________-->
<transmission name="head">
    <type>transmission_interface/SimpleTransmission</type>
    <joint name="head_body">
      <hardwareInterface>hardware_interface/EffortJointInterface</hardwareInterface>
    </joint>
    <actuator name="motor_head">
      <hardwareInterface>EffortJointInterface</hardwareInterface>
      <mechanicalReduction>1</mechanicalReduction>
    </actuator>
</transmission>

<transmission name="lu1">
    <type>transmission_interface/SimpleTransmission</type>
    <joint name="right_hand">
      <hardwareInterface>hardware_interface/EffortJointInterface</hardwareInterface>
    </joint>
    <actuator name="motor1">
      <hardwareInterface>EffortJointInterface</hardwareInterface>
      <mechanicalReduction>1</mechanicalReduction>
    </actuator>
  </transmission>
<transmission name="lb1">
    <type>transmission_interface/SimpleTransmission</type>
    <joint name="lower_upper1">
      <hardwareInterface>hardware_interface/EffortJointInterface</hardwareInterface>
    </joint>
    <actuator name="motor2">
      <hardwareInterface>EffortJointInterface</hardwareInterface>
      <mechanicalReduction>1</mechanicalReduction>
    </actuator>
</transmission>

<transmission name="lu2">
    <type>transmission_interface/SimpleTransmission</type>
    <joint name="right_leg">
      <hardwareInterface>hardware_interface/EffortJointInterface</hardwareInterface>
    </joint>
    <actuator name="motor3">
      <hardwareInterface>EffortJointInterface</hardwareInterface>
      <mechanicalReduction>1</mechanicalReduction>
    </actuator>
  </transmission>
<transmission name="lb2">
    <type>transmission_interface/SimpleTransmission</type>
    <joint name="lower_upper2">
      <hardwareInterface>hardware_interface/EffortJointInterface</hardwareInterface>
    </joint>
    <actuator name="motor4">
      <hardwareInterface>EffortJointInterface</hardwareInterface>
      <mechanicalReduction>1</mechanicalReduction>
    </actuator>
</transmission>

<transmission name="lu3">
    <type>transmission_interface/SimpleTransmission</type>
    <joint name="left_leg">
      <hardwareInterface>hardware_interface/EffortJointInterface</hardwareInterface>
    </joint>
    <actuator name="motor5">
      <hardwareInterface>EffortJointInterface</hardwareInterface>
      <mechanicalReduction>1</mechanicalReduction>
    </actuator>
  </transmission>
<transmission name="lb3">
    <type>transmission_interface/SimpleTransmission</type>
    <joint name="lower_upper3">
      <hardwareInterface>hardware_interface/EffortJointInterface</hardwareInterface>
    </joint>
    <actuator name="motor6">
      <hardwareInterface>EffortJointInterface</hardwareInterface>
      <mechanicalReduction>1</mechanicalReduction>
    </actuator>
  </transmission>
<transmission name="lu4">
    <type>transmission_interface/SimpleTransmission</type>
    <joint name="left_hand">
      <hardwareInterface>hardware_interface/EffortJointInterface</hardwareInterface>
    </joint>
    <actuator name="motor7">
      <hardwareInterface>EffortJointInterface</hardwareInterface>
      <mechanicalReduction>1</mechanicalReduction>
    </actuator>
  </transmission>
<transmission name="lb4">
    <type>transmission_interface/SimpleTransmission</type>
    <joint name="lower_upper4">
      <hardwareInterface>hardware_interface/EffortJointInterface</hardwareInterface>
    </joint>
    <actuator name="motor8">
      <hardwareInterface>EffortJointInterface</hardwareInterface>
      <mechanicalReduction>1</mechanicalReduction>
    </actuator>
</transmission>


<gazebo>
  <plugin name="gazebo_ros_control" filename="libgazebo_ros_control.so">
    <robotNamespace>/billi/default_controller</robotNamespace>
    <robotSimType>gazebo_ros_control/DefaultRobotHWSim</robotSimType>
  </plugin>
</gazebo>

</robot>
