<?xml version="1.0"?>

<robot name="billi" xmlns:xacro="http://www.ros.org/wiki/xacro">

  <!-- billi shoulder -->
<<<<<<< HEAD
	<!--xacro:include filename="$(find billi_sim)/models/urdf/shoulder.xacro"/-->
=======
	<xacro:include filename="$(find billi_sim)/models/urdf/shoulder.xacro"/>
>>>>>>> a2351546f9e6cd629167bb84ce18117092a4d7df
	<!-- billi body -->
	<xacro:include filename="$(find billi_sim)/models/urdf/body.xacro"/>

    <!-- billi leg -->
<<<<<<< HEAD
	<xacro:include filename="$(find billi_sim)/models/urdf/leg1.xacro"/>
	<xacro:include filename="$(find billi_sim)/models/urdf/leg2.xacro"/>
	<xacro:include filename="$(find billi_sim)/models/urdf/leg3.xacro"/>
	<xacro:include filename="$(find billi_sim)/models/urdf/leg4.xacro"/>
	<xacro:include filename="$(find billi_sim)/models/urdf/leg-lower4.xacro"/>
	<xacro:include filename="$(find billi_sim)/models/urdf/leg-lower2.xacro"/>
	<xacro:include filename="$(find billi_sim)/models/urdf/leg-lower1.xacro"/>
	<xacro:include filename="$(find billi_sim)/models/urdf/leg-lower3.xacro"/>
=======
	<xacro:include filename="$(find billi_sim)/models/urdf/leg.xacro"/>

>>>>>>> a2351546f9e6cd629167bb84ce18117092a4d7df

    <!-- billi head -->
	<xacro:include filename="$(find billi_sim)/models/urdf/head.xacro"/>


<<<<<<< HEAD
	<!--gazebo>
		<plugin name="gazebo_ros_control" filename="libgazebo_ros_control.so"/>
	</gazebo-->
=======
	<gazebo>
		<plugin name="gazebo_ros_control" filename="libgazebo_ros_control.so"/>
	</gazebo>
>>>>>>> a2351546f9e6cd629167bb84ce18117092a4d7df

	<!-- body -->
	<!-- <xacro:billi_body name="base"/> -->

<<<<<<< HEAD
<joint name="lower_upper1" type="revolute">
			<origin xyz="0.0 -0.039282 0.0" rpy="0 0 0"/>
			<parent link="leg1"/>
			<child  link="leg-lower1"/>
			<axis xyz="0 0 1"/>
			<limit effort="150.0" velocity="12.0"
          lower="-1.57"
		  upper="1.57"/>
	</joint>
<gazebo reference="lower_upper1">
		<provideFeedback>true</provideFeedback>
		<disableFixedJointLumping>true</disableFixedJointLumping>
		</gazebo>
<joint name="lower_upper2" type="revolute">
			<origin xyz="0.0 -0.039282 0.0" rpy="0 0 0"/>
			<parent link="leg2"/>
			<child  link="leg-lower2"/>
			<axis xyz="0 0 1"/>
			<limit effort="150.0" velocity="12.0"
          lower="-1.57"
		  upper="1.57"/>
	</joint>
<gazebo reference="lower_upper2">
		<provideFeedback>true</provideFeedback>
		<disableFixedJointLumping>true</disableFixedJointLumping>
		</gazebo>

<joint name="lower_upper4" type="revolute">
			<origin xyz="0.0 -0.039282 0.0" rpy="0 0 0"/>
			<parent link="leg4"/>
			<child  link="leg-lower4"/>
			<axis xyz="0 0 1"/>
			<limit effort="150.0" velocity="12.0"
          lower="-1.57"
		  upper="1.57"/>
	</joint>
<gazebo reference="lower_upper4">
		<provideFeedback>true</provideFeedback>
		<disableFixedJointLumping>true</disableFixedJointLumping>
		</gazebo>

<joint name="lower_upper3" type="revolute">
			<origin xyz="0.0 -0.039282 0.0" rpy="0 0 0"/>
			<parent link="leg3"/>
			<child  link="leg-lower3"/>
			<axis xyz="0 0 1"/>
			<limit effort="150.0" velocity="12.0"
          lower="-1.57"
		  upper="1.57"/>
	</joint>
<gazebo reference="lower_upper3">
		<provideFeedback>true</provideFeedback>
		<disableFixedJointLumping>true</disableFixedJointLumping>
		</gazebo>



    <joint name="head_body" type="revolute">
			<origin xyz="0.098 0.035 -0.048" rpy="0 0 0"/>
=======
    <joint name="head_body" type="revolute">
			<origin xyz="0 0 0" rpy="0 0 0"/>
>>>>>>> a2351546f9e6cd629167bb84ce18117092a4d7df
			<parent link="body"/>
			<child  link="head"/>
			<axis xyz="0 0 1"/>
			<limit effort="150.0" velocity="12.0"
          lower="-1.57"
		  upper="1.57"/>
	</joint>
<gazebo reference="head_body">
		<provideFeedback>true</provideFeedback>
		<disableFixedJointLumping>true</disableFixedJointLumping>
		</gazebo>

    <joint name="right_hand" type="revolute">
			<origin xyz="0 0 0" rpy="0 0 0"/>
			<parent link="body"/>
			<child  link="leg1"/>
<<<<<<< HEAD
			<axis xyz="0 0 1"/>
=======
			<axis xyz="1 0 0"/>
>>>>>>> a2351546f9e6cd629167bb84ce18117092a4d7df
			<limit effort="150.0" velocity="12.0"
          lower="-1.57"
		  upper="1.57"/>
	</joint>
	<gazebo reference="right_hand">
		<provideFeedback>true</provideFeedback>
		<disableFixedJointLumping>true</disableFixedJointLumping>
		</gazebo>


   <joint name="left_hand" type="revolute">
<<<<<<< HEAD
			<origin xyz="0 0 -0.092" rpy="0 0 0"/>
			<parent link="body"/>
			<child  link="leg4"/>
			<axis xyz="0 0 1"/>
=======
			<origin xyz="0 0 0" rpy="0 0 0"/>
			<parent link="body"/>
			<child  link="leg2"/>
			<axis xyz="1 0 0"/>
>>>>>>> a2351546f9e6cd629167bb84ce18117092a4d7df
			<limit effort="150.0" velocity="12.0"
          lower="-1.57"
		  upper="1.57"/>
	</joint>
<gazebo reference="left_hand">
		<provideFeedback>true</provideFeedback>
		<disableFixedJointLumping>true</disableFixedJointLumping>
		</gazebo>

 <joint name="right_leg" type="revolute">
<<<<<<< HEAD
			<origin xyz=".083 .017 0" rpy="0 0 0"/>
			<parent link="body"/>
			<child  link="leg2"/>
			<axis xyz="0 0 1"/>
=======
			<origin xyz="0 0 0" rpy="0 0 0"/>
			<parent link="body"/>
			<child  link="leg1"/>
			<axis xyz="1 0 0"/>
>>>>>>> a2351546f9e6cd629167bb84ce18117092a4d7df
			<limit effort="150.0" velocity="12.0"
          lower="-1.57"
		  upper="1.57"/>
	</joint>
	<gazebo reference="right_leg">
			<provideFeedback>true</provideFeedback>
			<disableFixedJointLumping>true</disableFixedJointLumping>
			</gazebo>

    <joint name="left_leg" type="revolute">
<<<<<<< HEAD
			<origin xyz="0.083 0.017 -0.092" rpy="0 0 0"/>
			<parent link="body"/>
			<child  link="leg3"/>
			<axis xyz="0 0 1"/>
=======
			<origin xyz="0 0 0" rpy="0 0 0"/>
			<parent link="body"/>
			<child  link="leg2"/>
			<axis xyz="1 0 0"/>
>>>>>>> a2351546f9e6cd629167bb84ce18117092a4d7df
			<limit effort="150.0" velocity="12.0"
          lower="-1.57"
		  upper="1.57"/>
	</joint>
	<gazebo reference="left_leg">
		<provideFeedback>true</provideFeedback>
		<disableFixedJointLumping>true</disableFixedJointLumping>
		</gazebo>
<<<<<<< HEAD
<!-- Adding transmissions-->
<transmission name="head">
    <type>transmission_interface/SimpleTransmission</type>
    <joint name="head_body">
      <hardwareInterface>hardware_interface/EffortJointInterface</hardwareInterface>
    </joint>
    <actuator name="motor_head">
      <hardwareInterface>EffortJointInterface</hardwareInterface>
      <mechanicalReduction>1</mechanicalReduction>
    </actuator>
  </transmission>

<transmission name="lu1">
    <type>transmission_interface/SimpleTransmission</type>
    <joint name="right_hand">
      <hardwareInterface>hardware_interface/EffortJointInterface</hardwareInterface>
    </joint>
    <actuator name="motor1">
      <hardwareInterface>EffortJointInterface</hardwareInterface>
      <mechanicalReduction>1</mechanicalReduction>
    </actuator>
  </transmission>
<transmission name="lb1">
    <type>transmission_interface/SimpleTransmission</type>
    <joint name="lower_upper1">
      <hardwareInterface>hardware_interface/EffortJointInterface</hardwareInterface>
    </joint>
    <actuator name="motor2">
      <hardwareInterface>EffortJointInterface</hardwareInterface>
      <mechanicalReduction>1</mechanicalReduction>
    </actuator>
  </transmission>

<transmission name="lu2">
    <type>transmission_interface/SimpleTransmission</type>
    <joint name="right_leg">
      <hardwareInterface>hardware_interface/EffortJointInterface</hardwareInterface>
    </joint>
    <actuator name="motor3">
      <hardwareInterface>EffortJointInterface</hardwareInterface>
      <mechanicalReduction>1</mechanicalReduction>
    </actuator>
  </transmission>
<transmission name="lb2">
    <type>transmission_interface/SimpleTransmission</type>
    <joint name="lower_upper2">
      <hardwareInterface>hardware_interface/EffortJointInterface</hardwareInterface>
    </joint>
    <actuator name="motor4">
      <hardwareInterface>EffortJointInterface</hardwareInterface>
      <mechanicalReduction>1</mechanicalReduction>
    </actuator>
  </transmission>

<transmission name="lu3">
    <type>transmission_interface/SimpleTransmission</type>
    <joint name="left_leg">
      <hardwareInterface>hardware_interface/EffortJointInterface</hardwareInterface>
    </joint>
    <actuator name="motor5">
      <hardwareInterface>EffortJointInterface</hardwareInterface>
      <mechanicalReduction>1</mechanicalReduction>
    </actuator>
  </transmission>
<transmission name="lb3">
    <type>transmission_interface/SimpleTransmission</type>
    <joint name="lower_upper3">
      <hardwareInterface>hardware_interface/EffortJointInterface</hardwareInterface>
    </joint>
    <actuator name="motor6">
      <hardwareInterface>EffortJointInterface</hardwareInterface>
      <mechanicalReduction>1</mechanicalReduction>
    </actuator>
  </transmission>
<transmission name="lu4">
    <type>transmission_interface/SimpleTransmission</type>
    <joint name="left_hand">
      <hardwareInterface>hardware_interface/EffortJointInterface</hardwareInterface>
    </joint>
    <actuator name="motor7">
      <hardwareInterface>EffortJointInterface</hardwareInterface>
      <mechanicalReduction>1</mechanicalReduction>
    </actuator>
  </transmission>
<transmission name="lb4">
    <type>transmission_interface/SimpleTransmission</type>
    <joint name="lower_upper4">
      <hardwareInterface>hardware_interface/EffortJointInterface</hardwareInterface>
    </joint>
    <actuator name="motor8">
      <hardwareInterface>EffortJointInterface</hardwareInterface>
      <mechanicalReduction>1</mechanicalReduction>
    </actuator>
  </transmission>
<gazebo>
  <plugin name="gazebo_ros_control" filename="libgazebo_ros_control.so">
    <robotNamespace>/billi/default_controller</robotNamespace>
    <robotSimType>gazebo_ros_control/DefaultRobotHWSim</robotSimType>
  </plugin>
</gazebo>
</robot>
    
=======

</robot>
    
>>>>>>> a2351546f9e6cd629167bb84ce18117092a4d7df
