<?xml version="1.0"?>

<robot xmlns:xacro="http://www.ros.org/wiki/xacro">

	<!-- leg macro definiction -->
	<xacro:macro name="hyq_leg" params="name parent *origin reflect_hip reflect_upper reflect_front">
		<!-- Joints -->
		<!-- Hip assembly joint -->
		<joint name="${name}_haa_joint" type="revolute">
			<xacro:insert_block name="origin"/>
			<parent link="${parent}"/>
			<child  link="${name}_hipassembly"/>
			<axis xyz="0 0 1"/>
			<limit effort="150.0" velocity="12.0" lower="${-7*PI/18}" upper="${PI/6}"/>
		</joint>
		<gazebo reference="${name}_haa_joint">
			<provideFeedback>true</provideFeedback>
			<disableFixedJointLumping>true</disableFixedJointLumping>
		</gazebo>
		
		<!-- Upper leg joint -->
		<joint name="${name}_hfe_joint" type="revolute">
			<origin xyz="${d_tbb} 0 0" rpy="${reflect_upper*PI/2} 0 0"/>
			<parent link="${name}_hipassembly"/>
			<child  link="${name}_upperleg"/>
			<axis xyz="0 0 1"/>
			<limit effort="150.0" velocity="12.0"
          lower="${-(1+reflect_front)*5*PI/36-(1-reflect_front)*7*PI/36}"
		  upper="${(1-reflect_front)*5*PI/36+(1+reflect_front)*7*PI/36}"/>
		</joint>
		<gazebo reference="${name}_hfe_joint">
		<provideFeedback>true</provideFeedback>
		<disableFixedJointLumping>true</disableFixedJointLumping>
		</gazebo>
		
		<!-- Lower leg joint -->
		<joint name="${name}_kfe_joint" type="revolute">
			<origin xyz="${d_p1p2} 0 0" rpy="0 0 0"/>
			<parent link="${name}_upperleg"/>
			<child  link="${name}_lowerleg"/>
			<axis xyz="0 0 1"/>
			<limit effort="150.0" velocity="12.0"
          lower="${-(1+reflect_front)*7*PI/18+(1-reflect_front)*PI/18}"
		  upper="${(1-reflect_front)*7*PI/18-(1+reflect_front)*PI/18}"/>
		</joint>
		<gazebo reference="${name}_kfe_joint">
		<provideFeedback>true</provideFeedback>
		<disableFixedJointLumping>true</disableFixedJointLumping>
		</gazebo>

		<!-- Foot joint -->
		<joint name="${name}_foot_joint" type="fixed">
			<origin xyz="0.35 0 0" rpy="${PI/2} 0 ${-PI/2}"/>
			<parent link="${name}_lowerleg"/>
			<child  link="${name}_foot"/>
		</joint>
		<gazebo reference="${name}_foot_joint">
			<provideFeedback>true</provideFeedback>
			<disableFixedJointLumping>true</disableFixedJointLumping>
		</gazebo>

		<!-- Links -->
		<!-- Hip assembly link -->
		<link name="${name}_hipassembly">
			<visual>
				<origin xyz="0 0 0" rpy="${(1-reflect_hip)*PI/2} 0 0"/>
				<geometry>
					<mesh filename="package://towr_simulator/models/meshes/leg/hipassembly.dae" scale="1 1 1"/>
				</geometry>
			</visual>
			<collision>
				<origin xyz="0 0 0" rpy="${(1-reflect_hip)*PI/2} 0 0"/>
				<geometry>
					<mesh filename="package://towr_simulator/models/meshes/leg/hipassembly.dae" scale="1 1 1"/>
				</geometry>
			</collision>
			<inertial>
				<origin xyz="0 0 0"/>
				<mass value="1.0"/>
				<inertia ixx="0.1" ixy="0.0" ixz="0.0" iyy="0.1" iyz="0.0" izz="0.1"/>
			</inertial>	
		</link>
		<gazebo reference="${name}_hipassembly"/>
		
		<!-- Upper leg link -->
		<link name="${name}_upperleg">
			<visual> 
				<origin xyz="0 0 0" rpy="${(1-reflect_front)*PI/2} 0 0"/>
				<geometry>
					<mesh filename="package://towr_simulator/models/meshes/leg/upperleg.dae" scale="1 1 1"/>
				</geometry>
			</visual>
			<collision>
				<origin xyz="0 0 0" rpy="${(1-reflect_front)*PI/2} 0 0"/>
				<geometry>
					<mesh filename="package://towr_simulator/models/meshes/leg/upperleg.dae" scale="1 1 1"/>
				</geometry>
			</collision>
			<inertial>
				<origin xyz="0 0 0"/>
				<mass value="1.0"/>
				<inertia ixx="0.1" ixy="0.0" ixz="0.0" iyy="0.1" iyz="0.0" izz="0.1"/>
			</inertial>
		</link>
		<gazebo reference="${name}_upperleg"/>
		
		<!-- Lower leg link -->
		<link name="${name}_lowerleg">
			<visual>
				<geometry>
					<mesh filename="package://towr_simulator/models/meshes/leg/lowerleg.dae" scale="1 1 1"/>
				</geometry>
				<material name="white"/>
			</visual>
			<collision>
				<geometry>
					<mesh filename="package://towr_simulator/models/meshes/leg/lowerleg.dae" scale="1 1 1"/>
				</geometry>
			</collision>
			<inertial>
				<origin xyz="0 0 0"/>
				<mass value="1.0"/>
				<inertia ixx="0.1" ixy="0.0" ixz="0.0" iyy="0.1" iyz="0.0" izz="0.1"/>
			</inertial>
		</link>
		<gazebo reference="${name}_lowerleg"/>
		
		<!-- Foot link -->
		<link name="${name}_foot">
			<inertial>
				<origin xyz="0 0 0"/>
				<mass value="0.07"/>
				<inertia ixx="0.0000112" iyy="0.0000112" izz="0.0000112" ixy="0.0" ixz="0.0" iyz="0.0"/>
			</inertial>
			<collision>
				<origin xyz="0 0 0" rpy="0 0 0"/>
				<geometry>
					<sphere radius="0.02175"/>
				</geometry>
			</collision>
		</link>
		<gazebo reference="${name}_foot">
			<mu1>1</mu1>
			<mu2>1</mu2>
			<fdir1>1 0 0</fdir1>
			<maxContacts>1</maxContacts>
			<minDepth>0.005</minDepth>
			<gravity>true</gravity>
			<collision name="${name}_lowerleg_fixed_joint_lump__${name}_foot_collision_1">
					<geometry>
							<sphere>
									<!-- should be the same as surface_radius -->
									<radius>0.02175</radius>
							</sphere>
					</geometry>

			<surface>
					<friction>
							<torsional>
									<coefficient>10</coefficient>
									<use_patch_radius>false</use_patch_radius>
									<!-- should be the same as collision sphere radius -->
									<surface_radius>0.02175</surface_radius>
									<patch_radius>0.01</patch_radius>
							</torsional>
					</friction>
					<contact>
							<poissons_ratio>0.5</poissons_ratio>
							<elastic_modulus>1e8</elastic_modulus>
					</contact>
			</surface>
	</collision>

	<material>Gazebo/Black</material>
	</gazebo>
	</xacro:macro>

</robot>